<?xml version="1.0" encoding="utf-8"?>
<!-- This URDF was automatically created by SolidWorks to URDF Exporter! Originally created by Stephen Brawner (brawner@gmail.com) 
     Commit Version: 1.6.0-1-g15f4949  Build Version: 1.6.7594.29634
     For more information, please see http://wiki.ros.org/sw_urdf_exporter -->
<robot
  name="robot_description">
  <link
    name="dummy">
    <visual>
      <origin
        xyz="0 0 0"
        rpy="0 0 0" />
      <geometry>
        <mesh
          filename="package://robot_description/meshes/dummy.STL" />
      </geometry>
      <material
        name="">
        <color
          rgba="0.79216 0.81961 0.93333 1" />
      </material>
    </visual>
    <collision>
      <origin
        xyz="0 0 0"
        rpy="0 0 0" />
      <geometry>
        <mesh
          filename="package://robot_description/meshes/dummy.STL" />
      </geometry>
    </collision>
  </link>
  <link
    name="base_link">
    <inertial>
      <origin
        xyz="0.094802 0.023476 0.089613"
        rpy="0 0 0" />
      <mass
        value="0.041621" />
      <inertia
        ixx="2.1209E-05"
        ixy="-1.3206E-10"
        ixz="2.5764E-10"
        iyy="2.3001E-05"
        iyz="8.8145E-09"
        izz="4.3695E-05" />
    </inertial>
    <visual>
      <origin
        xyz="0 0 0"
        rpy="0 0 0" />
      <geometry>
        <mesh
          filename="package://robot_description/meshes/base_link.STL" />
      </geometry>
      <material
        name="">
        <color
          rgba="0.79216 0.81961 0.93333 1" />
      </material>
    </visual>
    <collision>
      <origin
        xyz="0 0 0"
        rpy="0 0 0" />
      <geometry>
        <mesh
          filename="package://robot_description/meshes/base_link.STL" />
      </geometry>
    </collision>
  </link>
  <joint
    name="dummy"
    type="fixed">
    <origin
      xyz="0 0 0"
      rpy="0 0 0" />
    <parent
      link="dummy" />
    <child
      link="base_link" />
    <axis
      xyz="0 0 0" />
  </joint>
  <link
    name="link_1">
    <inertial>
      <origin
        xyz="-0.006455 -0.0026486 0.016101"
        rpy="0 0 0" />
      <mass
        value="0.079808" />
      <inertia
        ixx="2.4245E-05"
        ixy="-3.9646E-08"
        ixz="1.7004E-09"
        iyy="2.9109E-05"
        iyz="4.4379E-07"
        izz="4.9332E-05" />
    </inertial>
    <visual>
      <origin
        xyz="0 0 0"
        rpy="0 0 0" />
      <geometry>
        <mesh
          filename="package://robot_description/meshes/link_1.STL" />
      </geometry>
      <material
        name="">
        <color
          rgba="0.75294 0.75294 0.75294 1" />
      </material>
    </visual>
    <collision>
      <origin
        xyz="0 0 0"
        rpy="0 0 0" />
      <geometry>
        <mesh
          filename="package://robot_description/meshes/link_1.STL" />
      </geometry>
    </collision>
  </link>
  <joint
    name="joint_0"
    type="revolute">
    <origin
      xyz="0.094802 0.02178 0.094485"
      rpy="0 0 0" />
    <parent
      link="base_link" />
    <child
      link="link_1" />
    <axis
      xyz="0 0 1" />
    <limit
      lower="-4.1888"
      upper="0.69813"
      effort="0"
      velocity="0" />
  </joint>
  <link
    name="link_2">
    <inertial>
      <origin
        xyz="-0.0441672955930066 -0.0254999999999995 0.00196123940117489"
        rpy="0 0 0" />
      <mass
        value="0.04759938537894" />
      <inertia
        ixx="3.33319565488529E-05"
        ixy="-6.9117387543481E-06"
        ixz="-2.96183751814742E-21"
        iyy="4.13129450096359E-05"
        iyz="2.78246571699322E-20"
        izz="2.0881605962112E-05" />
    </inertial>
    <visual>
      <origin
        xyz="0 0 0"
        rpy="0 0 0" />
      <geometry>
        <mesh
          filename="package://robot_description/meshes/link_2.STL" />
      </geometry>
      <material
        name="">
        <color
          rgba="0.752941176470588 0.752941176470588 0.752941176470588 1" />
      </material>
    </visual>
    <collision>
      <origin
        xyz="0 0 0"
        rpy="0 0 0" />
      <geometry>
        <mesh
          filename="package://robot_description/meshes/link_2.STL" />
      </geometry>
    </collision>
  </link>
  <joint
    name="joint_1"
    type="revolute">
    <origin
      xyz="-0.0017545 0 0.0249"
      rpy="-1.5708 0 0" />
    <parent
      link="link_1" />
    <child
      link="link_2" />
    <axis
      xyz="0 0 1" />
    <limit
      lower="-0.17453"
      upper="1.7453"
      effort="0"
      velocity="0" />
  </joint>
  <link
    name="link_3">
    <inertial>
      <origin
        xyz="0.0554376610188381 0.00312319498710001 -0.00374536272571629"
        rpy="0 0 0" />
      <mass
        value="0.111344912824329" />
      <inertia
        ixx="1.09688048932566E-05"
        ixy="-1.78460277050349E-09"
        ixz="-9.02393554790872E-08"
        iyy="2.46157246976635E-05"
        iyz="-8.55982045464642E-07"
        izz="2.27017675785582E-05" />
    </inertial>
    <visual>
      <origin
        xyz="0 0 0"
        rpy="0 0 0" />
      <geometry>
        <mesh
          filename="package://robot_description/meshes/link_3.STL" />
      </geometry>
      <material
        name="">
        <color
          rgba="0.752941176470588 0.752941176470588 0.752941176470588 1" />
      </material>
    </visual>
    <collision>
      <origin
        xyz="0 0 0"
        rpy="0 0 0" />
      <geometry>
        <mesh
          filename="package://robot_description/meshes/link_3.STL" />
      </geometry>
    </collision>
  </link>
  <joint
    name="joint_2"
    type="revolute">
    <origin
      xyz="-0.088335 -0.051 0"
      rpy="0 0 -1.0472" />
    <parent
      link="link_2" />
    <child
      link="link_3" />
    <axis
      xyz="0 0 1" />
    <limit
      lower="-1.5"
      upper="1.12"
      effort="0"
      velocity="0" />
  </joint>
  <link
    name="link_4">
    <inertial>
      <origin
        xyz="-0.0176379229960773 0.0305437128442724 0.00159557678617681"
        rpy="0 0 0" />
      <mass
        value="0.0508687992629349" />
      <inertia
        ixx="2.36967919956933E-05"
        ixy="2.48979389762864E-06"
        ixz="-1.97394708975074E-08"
        iyy="2.08307216385514E-05"
        iyz="3.41880636763051E-08"
        izz="9.91099451712242E-06" />
    </inertial>
    <visual>
      <origin
        xyz="0 0 0"
        rpy="0 0 0" />
      <geometry>
        <mesh
          filename="package://robot_description/meshes/link_4.STL" />
      </geometry>
      <material
        name="">
        <color
          rgba="0.752941176470588 0.752941176470588 0.752941176470588 1" />
      </material>
    </visual>
    <collision>
      <origin
        xyz="0 0 0"
        rpy="0 0 0" />
      <geometry>
        <mesh
          filename="package://robot_description/meshes/link_4.STL" />
      </geometry>
    </collision>
  </link>
  <joint
    name="joint_3"
    type="revolute">
    <origin
      xyz="0.13051 0 0"
      rpy="0.033013 0 0" />
    <parent
      link="link_3" />
    <child
      link="link_4" />
    <axis
      xyz="0 0 1" />
    <limit
      lower="-2.5"
      upper="0.17"
      effort="0"
      velocity="0" />
  </joint>
  <link
    name="link_5">
    <inertial>
      <origin
        xyz="0.000145826433482737 0.00572759346298343 0.0249754325019977"
        rpy="0 0 0" />
      <mass
        value="0.0397478662209852" />
      <inertia
        ixx="4.82308554751759E-06"
        ixy="-5.41076945991279E-08"
        ixz="-2.14243371035978E-06"
        iyy="6.53212892558204E-06"
        iyz="4.8597350438789E-07"
        izz="4.2080310033455E-06" />
    </inertial>
    <visual>
      <origin
        xyz="0 0 0"
        rpy="0 0 0" />
      <geometry>
        <mesh
          filename="package://robot_description/meshes/link_5.STL" />
      </geometry>
      <material
        name="">
        <color
          rgba="0.752941176470588 0.752941176470588 0.752941176470588 1" />
      </material>
    </visual>
    <collision>
      <origin
        xyz="0 0 0"
        rpy="0 0 0" />
      <geometry>
        <mesh
          filename="package://robot_description/meshes/link_5.STL" />
      </geometry>
    </collision>
  </link>
  <joint
    name="joint_4"
    type="revolute">
    <origin
      xyz="-0.043854 0.075958 -0.008714"
      rpy="-0.11661 -0.71223 -1.8407" />
    <parent
      link="link_4" />
    <child
      link="link_5" />
    <axis
      xyz="0.53086 0.7613 -0.37231" />
    <limit
      lower="-0.1"
      upper="0.1"
      effort="0"
      velocity="0" />
  </joint>
  <link
    name="link_51">
    <inertial>
      <origin
        xyz="0.0274973854492597 0.00666645635188887 -0.00274999999999825"
        rpy="0 0 0" />
      <mass
        value="0.00141569349834304" />
      <inertia
        ixx="2.12882327783662E-07"
        ixy="-2.23055006855443E-08"
        ixz="-7.42187804613204E-22"
        iyy="4.99683964313318E-08"
        iyz="-4.00355416475665E-22"
        izz="2.61906928549432E-07" />
    </inertial>
    <visual>
      <origin
        xyz="0 0 0"
        rpy="0 0 0" />
      <geometry>
        <mesh
          filename="package://robot_description/meshes/link_51.STL" />
      </geometry>
      <material
        name="">
        <color
          rgba="0.792156862745098 0.819607843137255 0.933333333333333 1" />
      </material>
    </visual>
    <collision>
      <origin
        xyz="0 0 0"
        rpy="0 0 0" />
      <geometry>
        <mesh
          filename="package://robot_description/meshes/link_51.STL" />
      </geometry>
    </collision>
  </link>
  <joint
    name="joint_5"
    type="revolute">
    <origin
      xyz="0.0061729 -0.0095263 0.010922"
      rpy="0.60214 0.85354 3.0106" />
    <parent
      link="link_5" />
    <child
      link="link_51" />
    <axis
      xyz="0 0 1" />
    <limit
      lower="0.1"
      upper="0.92"
      effort="0"
      velocity="0" />
  </joint>
  <link
    name="link_52">
    <inertial>
      <origin
        xyz="0.0273537886684804 0.0226207279404789 0.00150000000000955"
        rpy="0 0 0" />
      <mass
        value="0.00148390327012937" />
      <inertia
        ixx="4.30795368940953E-07"
        ixy="8.24295843502233E-08"
        ixz="-5.36426627240638E-22"
        iyy="3.23578805228052E-08"
        iyz="1.86363792008197E-21"
        izz="4.60927394558564E-07" />
    </inertial>
    <visual>
      <origin
        xyz="0 0 0"
        rpy="0 0 0" />
      <geometry>
        <mesh
          filename="package://robot_description/meshes/link_52.STL" />
      </geometry>
      <material
        name="">
        <color
          rgba="0.792156862745098 0.819607843137255 0.933333333333333 1" />
      </material>
    </visual>
    <collision>
      <origin
        xyz="0 0 0"
        rpy="0 0 0" />
      <geometry>
        <mesh
          filename="package://robot_description/meshes/link_52.STL" />
      </geometry>
    </collision>
  </link>
  <joint
    name="joint_51"
    type="revolute">
    <origin
      xyz="-0.0036089 0.030839 -0.00175"
      rpy="0 0 0" />
    <parent
      link="link_51" />
    <child
      link="link_52" />
    <axis
      xyz="0 0 -1" />
    <limit
      lower="0.1"
      upper="0.92"
      effort="0"
      velocity="0" />
    <mimic
      joint="joint_5"
      multiplier="1"
      offset="0" />
  </joint>
  <link
    name="link_53">
    <inertial>
      <origin
        xyz="-0.0275517174404179 0.00686942071701245 -0.0010000000000093"
        rpy="0 0 0" />
      <mass
        value="0.00137328199751958" />
      <inertia
        ixx="2.10770882639421E-07"
        ixy="2.30360067045727E-08"
        ixz="-1.54682774547416E-22"
        iyy="5.00701284621878E-08"
        iyz="9.42985898310452E-22"
        izz="2.59925489769929E-07" />
    </inertial>
    <visual>
      <origin
        xyz="0 0 0"
        rpy="0 0 0" />
      <geometry>
        <mesh
          filename="package://robot_description/meshes/link_53.STL" />
      </geometry>
      <material
        name="">
        <color
          rgba="0.792156862745098 0.819607843137255 0.933333333333333 1" />
      </material>
    </visual>
    <collision>
      <origin
        xyz="0 0 0"
        rpy="0 0 0" />
      <geometry>
        <mesh
          filename="package://robot_description/meshes/link_53.STL" />
      </geometry>
    </collision>
  </link>
  <joint
    name="joint_53"
    type="revolute">
    <origin
      xyz="-0.0105213588774655 -0.00832612259373461 -0.0104276575228075"
      rpy="0.602136293756852 0.853540316865174 3.01057033246525" />
    <parent
      link="link_5" />
    <child
      link="link_53" />
    <axis
      xyz="0 0 -1" />
    <limit
      lower="0.1"
      upper="0.92"
      effort="0"
      velocity="0" />
    <mimic
      joint="joint_5"
      multiplier="1"
      offset="0" />
  </joint>
  <link
    name="link_54">
    <inertial>
      <origin
        xyz="-0.027579568289924 0.0226489633076726 0.00149999999999034"
        rpy="0 0 0" />
      <mass
        value="0.00148390327012937" />
      <inertia
        ixx="4.32400053087531E-07"
        ixy="-7.84391167968696E-08"
        ixz="-5.04580173657347E-23"
        iyy="3.07531963762263E-08"
        iyz="-1.24077091882954E-23"
        izz="4.60927394558563E-07" />
    </inertial>
    <visual>
      <origin
        xyz="0 0 0"
        rpy="0 0 0" />
      <geometry>
        <mesh
          filename="package://robot_description/meshes/link_54.STL" />
      </geometry>
      <material
        name="">
        <color
          rgba="0.792156862745098 0.819607843137255 0.933333333333333 1" />
      </material>
    </visual>
    <collision>
      <origin
        xyz="0 0 0"
        rpy="0 0 0" />
      <geometry>
        <mesh
          filename="package://robot_description/meshes/link_54.STL" />
      </geometry>
    </collision>
  </link>
  <joint
    name="joint_54"
    type="revolute">
    <origin
      xyz="0.00344200446641575 0.0308579332581169 0"
      rpy="0 0 0" />
    <parent
      link="link_53" />
    <child
      link="link_54" />
    <axis
      xyz="0 0 1" />
    <limit
      lower="0.1"
      upper="0.92"
      effort="0"
      velocity="0" />
    <mimic
      joint="joint_5"
      multiplier="1"
      offset="0" />
  </joint>
  <link
    name="wh_fl">
    <inertial>
      <origin
        xyz="1.2461E-09 -5.444E-09 -0.020213"
        rpy="0 0 0" />
      <mass
        value="0.072755" />
      <inertia
        ixx="4.1437E-05"
        ixy="2.2475E-13"
        ixz="-5.4568E-11"
        iyy="4.1437E-05"
        iyz="3.9178E-11"
        izz="6.0865E-05" />
    </inertial>
    <visual>
      <origin
        xyz="0 0 0"
        rpy="0 0 0" />
      <geometry>
        <mesh
          filename="package://robot_description/meshes/wh_fl.STL" />
      </geometry>
      <material
        name="">
        <color
          rgba="0.79216 0.81961 0.93333 1" />
      </material>
    </visual>
    <collision>
      <origin
        xyz="0 0 0"
        rpy="0 0 0" />
      <geometry>
        <mesh
          filename="package://robot_description/meshes/wh_fl.STL" />
      </geometry>
    </collision>
  </link>
  <joint
    name="joint_fl"
    type="continuous">
    <origin
      xyz="0.0963024280776692 0.105267807682509 0.0379849148150617"
      rpy="1.5707963267949 1.5707963267949 0" />
    <parent
      link="base_link" />
    <child
      link="wh_fl" />
    <axis
      xyz="0 0 1" />
  </joint>
  <link
    name="wh_fr">
    <inertial>
      <origin
        xyz="1.24612446750216E-09 5.44468690966138E-09 0.0202134707623578"
        rpy="0 0 0" />
      <mass
        value="0.0727548969707371" />
      <inertia
        ixx="4.14370643466436E-05"
        ixy="-2.24304743032627E-13"
        ixz="5.4568370513912E-11"
        iyy="4.1437065416982E-05"
        iyz="3.91778084305756E-11"
        izz="6.08652668920378E-05" />
    </inertial>
    <visual>
      <origin
        xyz="0 0 0"
        rpy="0 0 0" />
      <geometry>
        <mesh
          filename="package://robot_description/meshes/wh_fr.STL" />
      </geometry>
      <material
        name="">
        <color
          rgba="0.792156862745098 0.819607843137255 0.933333333333333 1" />
      </material>
    </visual>
    <collision>
      <origin
        xyz="0 0 0"
        rpy="0 0 0" />
      <geometry>
        <mesh
          filename="package://robot_description/meshes/wh_fr.STL" />
      </geometry>
    </collision>
  </link>
  <joint
    name="joint_fr"
    type="continuous">
    <origin
      xyz="0.0963024280776703 -0.0617069066648054 0.0379849148150617"
      rpy="1.57079632679489 1.5707963267949 0" />
    <parent
      link="base_link" />
    <child
      link="wh_fr" />
    <axis
      xyz="0 0 1" />
  </joint>
  <link
    name="wh_br">
    <inertial>
      <origin
        xyz="1.2461E-09 5.4447E-09 0.020213"
        rpy="0 0 0" />
      <mass
        value="0.072755" />
      <inertia
        ixx="4.1437E-05"
        ixy="-2.243E-13"
        ixz="5.4568E-11"
        iyy="4.1437E-05"
        iyz="3.9178E-11"
        izz="6.0865E-05" />
    </inertial>
    <visual>
      <origin
        xyz="0 0 0"
        rpy="0 0 0" />
      <geometry>
        <mesh
          filename="package://robot_description/meshes/wh_br.STL" />
      </geometry>
      <material
        name="">
        <color
          rgba="0.79216 0.81961 0.93333 1" />
      </material>
    </visual>
    <collision>
      <origin
        xyz="0 0 0"
        rpy="0 0 0" />
      <geometry>
        <mesh
          filename="package://robot_description/meshes/wh_br.STL" />
      </geometry>
    </collision>
  </link>
  <joint
    name="joint_br"
    type="continuous">
    <origin
      xyz="-0.10369757192233 -0.0617069066648075 0.0379849148150618"
      rpy="1.57079632679489 1.5707963267949 0" />
    <parent
      link="base_link" />
    <child
      link="wh_br" />
    <axis
      xyz="0 0 1" />
  </joint>
  <link
    name="wh_bl">
    <inertial>
      <origin
        xyz="1.24651658092723E-09 -5.44738676389045E-09 -0.0202134707646456"
        rpy="0 0 0" />
      <mass
        value="0.0727548969777271" />
      <inertia
        ixx="4.14370643514696E-05"
        ixy="2.24604330069228E-13"
        ixz="-5.45680690220501E-11"
        iyy="4.14370654188499E-05"
        iyz="3.91752883076733E-11"
        izz="6.08652668947899E-05" />
    </inertial>
    <visual>
      <origin
        xyz="0 0 0"
        rpy="0 0 0" />
      <geometry>
        <mesh
          filename="package://robot_description/meshes/wh_bl.STL" />
      </geometry>
      <material
        name="">
        <color
          rgba="0.792156862745098 0.819607843137255 0.933333333333333 1" />
      </material>
    </visual>
    <collision>
      <origin
        xyz="0 0 0"
        rpy="0 0 0" />
      <geometry>
        <mesh
          filename="package://robot_description/meshes/wh_bl.STL" />
      </geometry>
    </collision>
  </link>
  <joint
    name="joint_bl"
    type="continuous">
    <origin
      xyz="-0.103697571922331 0.105267807682509 0.0379849148150615"
      rpy="1.5707963267949 1.5707963267949 0" />
    <parent
      link="base_link" />
    <child
      link="wh_bl" />
    <axis
      xyz="0 0 1" />
  </joint>
  <link
    name="camera_link">
    <inertial>
      <origin
        xyz="-0.013048499559092 0.000246197944511112 -6.05670440417191E-05"
        rpy="0 0 0" />
      <mass
        value="0.0447521991262699" />
      <inertia
        ixx="2.7277525325308E-05"
        ixy="2.44341503420267E-07"
        ixz="-1.17387243420198E-09"
        iyy="3.94471790856199E-06"
        iyz="-2.80091941881806E-09"
        izz="2.73620891189281E-05" />
    </inertial>
    <visual>
      <origin
        xyz="0 0 0"
        rpy="0 0 0" />
      <geometry>
        <mesh
          filename="package://robot_description/meshes/camera_link.STL" />
      </geometry>
      <material
        name="">
        <color
          rgba="0.792156862745098 0.819607843137255 0.933333333333333 1" />
      </material>
    </visual>
    <collision>
      <origin
        xyz="0 0 0"
        rpy="0 0 0" />
      <geometry>
        <mesh
          filename="package://robot_description/meshes/camera_link.STL" />
      </geometry>
    </collision>
  </link>
  <joint
    name="camera_joint"
    type="fixed">
    <origin
      xyz="0.209802428077669 0.0217804505088517 0.0713934534411303"
      rpy="0 0 0" />
    <parent
      link="base_link" />
    <child
      link="camera_link" />
    <axis
      xyz="0 0 0" />
  </joint>
</robot>